using ChatApp.Core.Domain.Exceptions;

namespace ChatApp.API.Middleware
{
    public class ErrorHandlingMiddleware : IMiddleware
    {
        private readonly ILogger<ErrorHandlingMiddleware> _logger;

        public ErrorHandlingMiddleware(ILogger<ErrorHandlingMiddleware> logger)
        {
            _logger = logger;
        }

        public async Task InvokeAsync(HttpContext context, RequestDelegate next)
        {
            try
            {
                await next.Invoke(context);
            }
            catch (ForbidException forbidException)
            {
                context.Response.StatusCode = 403;
                await context.Response.WriteAsync(forbidException.Message);
            }
            catch (BadRequestException badRequestException)
            {
                context.Response.StatusCode = 400;
                await context.Response.WriteAsync(badRequestException.Message);
            }
            catch (NotFoundException notFoundException)
            {
                context.Response.StatusCode = 404;
                await context.Response.WriteAsync(notFoundException.Message);
            }
            catch (UnauthorizedAccessException unauthorizedAccessException)
            {
                context.Response.StatusCode = 401;
                await context.Response.WriteAsync(unauthorizedAccessException.Message);
            }
            catch (InvalidOperationException invalidOperationException)
            {
                context.Response.StatusCode = 409;
                await context.Response.WriteAsync(invalidOperationException.Message);
            }
            catch (Exception ex)
            {
                _logger.LogError(ex, ex.Message);

                context.Response.StatusCode = 500;
                await context.Response.WriteAsync("An error occurred while processing your request.");
            }
        }
    }
}
